Workbook

Sheet GSTR-3B
B2: GSTR-3B [See rule 61(5)]
B5: GSTIN | E5: Year | H5: Sheet Status:
B6: Legal name of the registered person | E6: Month
B8: 3.1 Details of Outward Supplies and inward supplies liable to reverse charge
B9: Nature of Supplies | C9: Total Taxable value | D9: Integrated Tax | E9: Central Tax | F9: State/UT Tax | G9: Cess
B10: 1 | C10: 2 | D10: 3 | E10: 4 | F10: 5 | G10: 6
B11: (a) Outward Taxable supplies (other than zero rated, nil rated and exempted) | C11: 0 | D11: 0 | E11: 0 | F11: =E11 | G11: 0
B12: (b) Outward Taxable supplies (zero rated ) | C12: 0 | D12: 0 | G12: 0
B13: (c) Other Outward Taxable supplies (Nil rated, exempted) | C13: 0
B14: (d) Inward supplies (liable to reverse charge) | C14: 0 | D14: 0 | E14: 0 | F14: =E14 | G14: 0
B15: (e) Non-GST Outward supplies | C15: 0
B16: Total | C16: =SUM(C11:C15) | D16: =SUM(D11:D12) + D14 | E16: =E11 + E14 | F16: =F11 + F14 | G16: =SUM(G11:G12) + G14
B19: 3.1.1 Details of supplies notified under section 9(5) of the CGST Act, 2017 and corresponding provision in IGST/UTGST/SGST Acts
B20: Nature of Supplies | C20: Total Taxable value | D20: Integrated Tax | E20: Central Tax | F20: State/UT Tax | G20: Cess
B21: 1 | C21: 2 | D21: 3 | E21: 4 | F21: 5 | G21: 6
B22: (i) Taxable supplies on which electronic commerce operator pays tax u/s 9(5) [to be furnished by electronic commerce operator] | C22: 0 | D22: 0 | E22: 0 | F22: =E22 | G22: 0
B23: (ii) Taxable supplies made by registered person through electronic commerce operator, on which electronic commerce operator is required to pay tax u/s 9(5) [to be furnished by registered person making supplies through electronic commerce operator] | C23: 0
B24: Total | C24: =SUM(C22:C23) | D24: =D22 | E24: =E22 | F24: =F22 | G24: =G22
B27: 4. Eligible ITC
B28: (1) As per Rule 42 & 43 of SGST/CGST rules | C28: Integrated Tax | D28: Central Tax | E28: State/UT Tax | F28: Cess
B29: 1 | C29: 2 | D29: 3 | E29: 4 | F29: 5
B30: (A) ITC Available (Whether in full or part)
B31: (1) Import of goods | C31: 0 | F31: 0
B32: (2) Import of services | C32: 0 | F32: 0
B33: (3) Inward supplies liable to reverse charge (other than 1 &2 above) | C33: 0 | D33: 0 | E33: =D33 | F33: 0
B34: (4) Inward supplies from ISD | C34: 0 | D34: 0 | E34: =D34 | F34: 0
B35: (5) All other ITC | C35: 0 | D35: 0 | E35: =D35 | F35: 0
B36: (B) ITC Reversed
B37: (1) As per rules 38,42 & 43 of CGST Rules and section 17(5) | C37: 0 | D37: 0 | E37: =D37 | F37: 0
B38: (2) Others | C38: 0 | D38: 0 | E38: 0 | F38: 0
B39: (C) Net ITC Available (A)-(B) | C39: =SUM(ROUND(C31,2),ROUND(C32,2),ROUND(C33,2),ROUND(C34,2),ROUND(C35,2))-SUM(ROUND(C37,2),ROUND(C38,2)) | D39: =SUM(ROUND(D31,2),ROUND(D32,2),ROUND(D33,2),ROUND(D34,2),ROUND(D35,2))-SUM(ROUND(D37,2),ROUND(D38,2)) | E39: =SUM(ROUND(E31,2),ROUND(E32,2),ROUND(E33,2),ROUND(E34,2),ROUND(E35,2))-SUM(ROUND(E37,2),ROUND(E38,2)) | F39: =SUM(ROUND(F31,2),ROUND(F32,2),ROUND(F33,2),ROUND(F34,2),ROUND(F35,2))-SUM(ROUND(F37,2),ROUND(F38,2))
B40: (D) Other Details
B41: (1) ITC reclaimed which was reversed under Table 4(B)(2) in earlier tax period | C41: 0 | D41: 0 | E41: =D41 | F41: 0
B42: (2) Ineligible ITC under section 16(4) & ITC restricted due to PoS rules | C42: 0 | D42: 0 | E42: =D42 | F42: 0
B45: 5. Values of exempt, Nil-rated and non-GST inward supplies
B46: Nature of supplies | D46: Inter-State supplies | E46: Intra-state supplies
B47: 1 | D47: 2 | E47: 3
B48: From a supplier under composition scheme, Exempt and Nil rated supply | D48: 0 | E48: 0
B49: Non GST supply | D49: 0 | E49: 0
B50: Total | D50: 0 | E50: =SUM(E48:E49)
...

Sheet Sheet1
A1: 2017-18
A2: 2018-19
A3: 2019-20
A4: 2020-21
A5: 2021-22
A6: 2022-23
A7: 2023-24
A8: 2024-25
A9: 2025-26

Sheet Master
A1: POS
A2: 01-Jammu & Kashmir | B2: =IF(COUNTIF('GSTR-3B'!$B$88:$B$124,A2)>=1,"",ROW()) | C2: {=IF(ROW(A2:A39)-ROW(A2)+1>COUNT(B2:B39),"", INDEX(A:A,SMALL(B2:B39,ROW(INDIRECT("1:"&ROWS(A2:A39))))))}
A3: 02-Himachal Pradesh | B3: =IF(COUNTIF('GSTR-3B'!$B$88:$B$124,A3)>=1,"",ROW()) | C3: 02-Himachal Pradesh | U3: =SUM('GSTR-3B'!D88:D124)+SUM('GSTR-3B'!F88:F124)+SUM('GSTR-3B'!H88:H124)
A4: 03-Punjab | B4: =IF(COUNTIF('GSTR-3B'!$B$88:$B$124,A4)>=1,"",ROW()) | C4: 03-Punjab | U4: =IF('GSTR-3B'!C65 = 'GSTR-3B'!J74,)
A5: 04-Chandigarh | B5: =IF(COUNTIF('GSTR-3B'!$B$88:$B$124,A5)>=1,"",ROW()) | C5: 04-Chandigarh | U5: =IF('GSTR-3B'!D65 = 'GSTR-3B'!J75,)
A6: 05-Uttarakhand | B6: =IF(COUNTIF('GSTR-3B'!$B$88:$B$124,A6)>=1,"",ROW()) | C6: 05-Uttarakhand | U6: =IF('GSTR-3B'!E65 = 'GSTR-3B'!J76,)
A7: 06-Haryana | B7: =IF(COUNTIF('GSTR-3B'!$B$88:$B$124,A7)>=1,"",ROW()) | C7: 06-Haryana | U7: =IF('GSTR-3B'!F65 = 'GSTR-3B'!J77,)
A8: 07-Delhi | B8: =IF(COUNTIF('GSTR-3B'!$B$88:$B$124,A8)>=1,"",ROW()) | C8: 07-Delhi
A9: 08-Rajasthan | B9: =IF(COUNTIF('GSTR-3B'!$B$88:$B$124,A9)>=1,"",ROW()) | C9: 08-Rajasthan | F9: x
A10: 09-Uttar Pradesh | B10: =IF(COUNTIF('GSTR-3B'!$B$88:$B$124,A10)>=1,"",ROW()) | C10: 09-Uttar Pradesh
A11: 10-Bihar | B11: =IF(COUNTIF('GSTR-3B'!$B$88:$B$124,A11)>=1,"",ROW()) | C11: 10-Bihar
A12: 11-Sikkim | B12: =IF(COUNTIF('GSTR-3B'!$B$88:$B$124,A12)>=1,"",ROW()) | C12: 11-Sikkim
A13: 12-Arunachal Pradesh | B13: =IF(COUNTIF('GSTR-3B'!$B$88:$B$124,A13)>=1,"",ROW()) | C13: 12-Arunachal Pradesh
A14: 13-Nagaland | B14: =IF(COUNTIF('GSTR-3B'!$B$88:$B$124,A14)>=1,"",ROW()) | C14: 13-Nagaland
A15: 14-Manipur | B15: =IF(COUNTIF('GSTR-3B'!$B$88:$B$124,A15)>=1,"",ROW()) | C15: 14-Manipur
A16: 15-Mizoram | B16: =IF(COUNTIF('GSTR-3B'!$B$88:$B$124,A16)>=1,"",ROW()) | C16: 15-Mizoram
A17: 16-Tripura | B17: =IF(COUNTIF('GSTR-3B'!$B$88:$B$124,A17)>=1,"",ROW()) | C17: 16-Tripura
A18: 17-Meghalaya | B18: =IF(COUNTIF('GSTR-3B'!$B$88:$B$124,A18)>=1,"",ROW()) | C18: 17-Meghalaya
A19: 18-Assam | B19: =IF(COUNTIF('GSTR-3B'!$B$88:$B$124,A19)>=1,"",ROW()) | C19: 18-Assam
A20: 19-West Bengal | B20: =IF(COUNTIF('GSTR-3B'!$B$88:$B$124,A20)>=1,"",ROW()) | C20: 19-West Bengal
A21: 20-Jharkhand | B21: =IF(COUNTIF('GSTR-3B'!$B$88:$B$124,A21)>=1,"",ROW()) | C21: 20-Jharkhand
... A39: 97-Other Territory | B39: =IF(COUNTIF('GSTR-3B'!$B$88:$B$124,A39)>=1,"",ROW()) | C39: 97-Other Territory
